<robot name="roomba">
    <!-- Base footprint -->
    <link name="base_footprint"/>

    <!-- Fixed joint from base_footprint to base_link -->
    <joint name="base_joint" type="fixed">
        <parent link="base_footprint"/>
        <child link="base_link"/>
        <origin xyz="0 0 0.05" rpy="0 0 0"/>
    </joint>

    <!-- Cuerpo principal del robot -->
    <link name="base_link">
        <visual>
            <geometry>
                <cylinder length="0.1" radius="0.17"/>
            </geometry>
            <material name="black">
                <color rgba="0 0 0 1"/>
            </material>
        </visual>
        <collision>
            <geometry>
                <cylinder length="0.1" radius="0.17"/>
            </geometry>
        </collision>
        <inertial>
            <mass value="2.5"/>
            <origin xyz="0 0 0" rpy="0 0 0"/>
            <inertia ixx="0.1" ixy="0" ixz="0" iyy="0.1" iyz="0" izz="0.1"/>
        </inertial>
    </link>

    <!-- Rueda izquierda -->
    <joint name="left_wheel_joint" type="continuous">
        <parent link="base_link"/>
        <child link="left_wheel"/>
        <origin xyz="0 0.15 -0.025" rpy="-1.5708 0 0"/>
        <axis xyz="0 0 1"/>
    </joint>

    <link name="left_wheel">
        <visual>
            <geometry>
                <cylinder length="0.03" radius="0.035"/>
            </geometry>
            <material name="gray">
                <color rgba="0.5 0.5 0.5 1"/>
            </material>
        </visual>
        <collision>
            <geometry>
                <cylinder length="0.03" radius="0.035"/>
            </geometry>
        </collision>
    </link>

    <!-- Rueda derecha -->
    <joint name="right_wheel_joint" type="continuous">
        <parent link="base_link"/>
        <child link="right_wheel"/>
        <origin xyz="0 -0.15 -0.025" rpy="-1.5708 0 0"/>
        <axis xyz="0 0 1"/>
    </joint>

    <link name="right_wheel">
        <visual>
            <geometry>
                <cylinder length="0.03" radius="0.035"/>
            </geometry>
            <material name="gray">
                <color rgba="0.5 0.5 0.5 1"/>
            </material>
        </visual>
        <collision>
            <geometry>
                <cylinder length="0.03" radius="0.035"/>
            </geometry>
        </collision>
    </link>

    <!-- Rueda castor -->
    <joint name="caster_joint" type="fixed">
        <parent link="base_link"/>
        <child link="caster_wheel"/>
        <origin xyz="0.12 0 -0.05" rpy="0 0 0"/>
    </joint>

    <link name="caster_wheel">
        <visual>
            <geometry>
                <sphere radius="0.025"/>
            </geometry>
            <material name="gray">
                <color rgba="0.5 0.5 0.5 1"/>
            </material>
        </visual>
        <collision>
            <geometry>
                <sphere radius="0.025"/>
            </geometry>
        </collision>
        <inertial>
            <mass value="0.1"/>
            <origin xyz="0 0 0" rpy="0 0 0"/>
            <inertia ixx="0.001" ixy="0" ixz="0" iyy="0.001" iyz="0" izz="0.001"/>
        </inertial>
    </link>
</robot>